Workbook

Sheet antibiotic_map
A1: antibioticNM | B1: antibioticConceptCode | C1: antibioticAbbrev
A2: CEPHALOTHIN | B2: cephalothin | C2: =_xlfn.XLOOKUP(B2,antibiotic_code_map!$A$2:$A$10055,antibiotic_code_map!$B$2:$B$10055) -> CEF
A3: TRIMETHOPRIM/SULFAMETHOXAZOLE | B3: trimethoprim_sulfamethoxazole | C3: =_xlfn.XLOOKUP(B3,antibiotic_code_map!$A$2:$A$10055,antibiotic_code_map!$B$2:$B$10055) -> SXT
A4: AMIKACIN | B4: amikacin | C4: =_xlfn.XLOOKUP(B4,antibiotic_code_map!$A$2:$A$10055,antibiotic_code_map!$B$2:$B$10055) -> AMK
A5: AMOXICILLIN + CLAVULANATE | B5: amoxicillin_clavulanate | C5: =_xlfn.XLOOKUP(B5,antibiotic_code_map!$A$2:$A$10055,antibiotic_code_map!$B$2:$B$10055) -> AMC
A6: AMPICILLIN | B6: ampicillin | C6: =_xlfn.XLOOKUP(B6,antibiotic_code_map!$A$2:$A$10055,antibiotic_code_map!$B$2:$B$10055) -> AMP
A7: AMPICILLIN + SULBACTAM | B7: ampicillin_sulbactam | C7: =_xlfn.XLOOKUP(B7,antibiotic_code_map!$A$2:$A$10055,antibiotic_code_map!$B$2:$B$10055) -> SAM
A8: AZTREONAM | B8: aztreonam | C8: =_xlfn.XLOOKUP(B8,antibiotic_code_map!$A$2:$A$10055,antibiotic_code_map!$B$2:$B$10055) -> ATM
A9: CEFAZOLIN | B9: cefazolin | C9: =_xlfn.XLOOKUP(B9,antibiotic_code_map!$A$2:$A$10055,antibiotic_code_map!$B$2:$B$10055) -> CFZ
A10: CEFEPIME | B10: cefepime | C10: =_xlfn.XLOOKUP(B10,antibiotic_code_map!$A$2:$A$10055,antibiotic_code_map!$B$2:$B$10055) -> FEP
A11: CEFOTAXIME | B11: cefotaxime | C11: =_xlfn.XLOOKUP(B11,antibiotic_code_map!$A$2:$A$10055,antibiotic_code_map!$B$2:$B$10055) -> CTX
A12: CEFOXITIN | B12: cefoxitin | C12: =_xlfn.XLOOKUP(B12,antibiotic_code_map!$A$2:$A$10055,antibiotic_code_map!$B$2:$B$10055) -> FOX
A13: CEFTAZIDIME | B13: ceftazidime | C13: =_xlfn.XLOOKUP(B13,antibiotic_code_map!$A$2:$A$10055,antibiotic_code_map!$B$2:$B$10055) -> CAZ
... A366: TICARCILLIN + CLAVULANIC ACID | B366: ticarcillin_clavulanate | C366: =_xlfn.XLOOKUP(B366,antibiotic_code_map!$A$2:$A$10055,antibiotic_code_map!$B$2:$B$10055) -> TIM

Sheet antibiotic_code_map
A1: antibiotic_concept_code | B1: antibiotic_short_code | C1: enzyme_class | D1: enzyme
A2: amikacin | B2: AMK
A3: amoxicillin | B3: AMX
A4: amoxicillin_clavulanate | B4: AMC
A5: amphotericin_B | B5: AMB
A6: ampicillin | B6: AMP
A7: ampicillin_sulbactam | B7: SAM
A8: anidulafungin | B8: AFG
A9: azithromycin | B9: AZM
A10: azlocillin | B10: AZL
A11: aztreonam | B11: ATM
A12: aztreonam_avibactam | B12: ATM_AVI
A13: bacampicillin | B13: BAM
... A15: bedaquiline | B15: BDQ
A16: beta_lactamase | B16: BLAC | C16: beta_lactamase | D16: blaZ
A17: capreomycin | B17: CAP
A18: carbapenemase_imp | B18: CARBA | C18: carbapenemase | D18: IMP
A19: carbapenemase_kpc | B19: CARBA | C19: carbapenemase | D19: KPC
A20: carbapenemase_ndm | B20: CARBA | C20: carbapenemase | D20: NDM
A21: carbapenemase_other | B21: CARBA | C21: carbapenemase
A22: carbapenemase_oxa | B22: CARBA | C22: carbapenemase | D22: OXA
A23: carbapenemase_vim | B23: CARBA | C23: carbapenemase | D23: VIM
A24: carbenicillin | B24: CRB
A25: caspofungin | B25: CAS
A26: cefaclor | B26: CEC
A27: cefadroxil | B27: CFR
A28: cefamandole | B28: FAM
A29: cefazolin | B29: CFZ
A30: cefdinir | B30: CDR
A31: cefditoren | B31: DIT
A32: cefepime | B32: FEP
A33: cefiderocol | B33: FDC
A34: cefixime | B34: CFM
A35: cefmetazole | B35: CMZ
... A84: ethionamide | B84: ETO
A85: extended_spectrum_beta_lactamase | B85: ESBL | C85: ESBL
A86: fluconazole | B86: FLC
A87: flucytosine | B87: 5FC
A88: fosfomycin | B88: FOF
A89: fusidic_acid | B89: FA
...

Sheet notes
A1: Three-letter antimicrobial codes are generally based on WHONET's system
A2: https://whonet.org/WebDocs/WHONET_Antimicrobial_Codes.pdf
